2025-04-29 20:13:22,273 - trading_system.exchange.binanceusdm_connector - ERROR - [generic_connector.py:260] - Đã vượt quá số lần thử lại. Lỗi cuối cùng: 'spot'
2025-04-29 20:13:22,275 - trading_system.exchange.binanceusdm_connector - ERROR - [generic_connector.py:215] - Lỗi không xác định trong fetch_ohlcv: 'spot'
2025-04-29 20:13:22,277 - trading_system.exchange.binanceusdm_connector - ERROR - [generic_connector.py:215] - Lỗi không xác định trong fetch_ohlcv(BTC/USDT, 1h): [binanceusdm] Lỗi không xác định trong fetch_ohlcv: 'spot'
2025-04-29 20:13:22,279 - trading_system.historical_data_collector_binanceusdm - ERROR - [historical_data_collector.py:291] - Lỗi khi thu thập OHLCV cho BTC/USDT: [binanceusdm] Lỗi không xác định trong fetch_ohlcv(BTC/USDT, 1h): [binanceusdm] Lỗi không xác định trong fetch_ohlcv: 'spot'
2025-04-29 20:13:43,430 - trading_system.exchange.binanceusdm_connector - ERROR - [generic_connector.py:260] - Đã vượt quá số lần thử lại. Lỗi cuối cùng: 'spot'
2025-04-29 20:13:43,432 - trading_system.exchange.binanceusdm_connector - ERROR - [generic_connector.py:215] - Lỗi không xác định trong fetch_ohlcv: 'spot'
2025-04-29 20:13:43,434 - trading_system.exchange.binanceusdm_connector - ERROR - [generic_connector.py:215] - Lỗi không xác định trong fetch_ohlcv(BTC/USDT, 4h): [binanceusdm] Lỗi không xác định trong fetch_ohlcv: 'spot'
2025-04-29 20:13:43,436 - trading_system.historical_data_collector_binanceusdm - ERROR - [historical_data_collector.py:291] - Lỗi khi thu thập OHLCV cho BTC/USDT: [binanceusdm] Lỗi không xác định trong fetch_ohlcv(BTC/USDT, 4h): [binanceusdm] Lỗi không xác định trong fetch_ohlcv: 'spot'
