2025-04-30 14:19:59,596 - trading_system - ERROR - [main.py:286] - Lỗi khi xử lý dữ liệu: 'DataPipeline' object has no attribute 'run'
2025-04-30 14:19:59,597 - trading_system - ERROR - [main.py:762] - Lỗi không xử lý được: 'DataPipeline' object has no attribute 'run'
Traceback (most recent call last):
  File "E:\AI_AGENT\automated-trading-system\main.py", line 749, in main
    await system.process_data(command, **kwargs)
  File "E:\AI_AGENT\automated-trading-system\main.py", line 279, in process_data
    await self.run_data_pipeline(**kwargs)
  File "E:\AI_AGENT\automated-trading-system\main.py", line 533, in run_data_pipeline
    result_df = await data_pipeline.run(
AttributeError: 'DataPipeline' object has no attribute 'run'
